{"code": 0, "msg": "FAIL", "task_id": "202211161127035249677", "task_name": "whole process", "create_time": "20221116112703525030", "error": "Traceback (most recent call last):\n  File \"/home/jit/service/mpc/driver/task.py\", line 60, in persist\n    r = self.__future.result()\n  File \"/usr/lib/python3.6/concurrent/futures/_base.py\", line 425, in result\n    return self.__get_result()\n  File \"/usr/lib/python3.6/concurrent/futures/_base.py\", line 384, in __get_result\n    raise self._exception\n  File \"/usr/lib/python3.6/concurrent/futures/thread.py\", line 56, in run\n    result = self.fn(*self.args, **self.kwargs)\n  File \"/home/jit/service/mpc/SrcCode/main_dynamic_function.py\", line 29, in start_mpc\n    dv = DynamicVariables(config_cpt)\n  File \"/home/jit/service/mpc/SrcCode/Source/dynamic_function.py\", line 90, in __init__\n    party_data_length[0],\nIndexError: list index out of range\n"}