{"code": 0, "msg": "FAIL", "task_id": "20230106083331834984121", "task_name": "whole process", "create_time": "20230106083331835054", "error": "Traceback (most recent call last):\n  File \"/home/jit/service/mpc/driver/task.py\", line 60, in persist\n    r = self.__future.result()\n  File \"/usr/lib/python3.6/concurrent/futures/_base.py\", line 425, in result\n    return self.__get_result()\n  File \"/usr/lib/python3.6/concurrent/futures/_base.py\", line 384, in __get_result\n    raise self._exception\n  File \"/usr/lib/python3.6/concurrent/futures/thread.py\", line 56, in run\n    result = self.fn(*self.args, **self.kwargs)\n  File \"/home/jit/service/mpc/SrcCode/main_dynamic_function.py\", line 29, in start_mpc\n    dv = DynamicVariables(config_cpt)\n  File \"/home/jit/service/mpc/SrcCode/Source/dynamic_function.py\", line 96, in __init__\n    self.names['data' + str(party_i)].input_from(party_i)\n  File \"/home/jit/service/mpc/Compiler/types.py\", line 5477, in input_from\n    self.assign(input_from(player, size=len(self)))\n  File \"/home/jit/service/mpc/Compiler/types.py\", line 5378, in assign\n    other.store_in_mem(self.get_address(base, other.size))\n  File \"/home/jit/service/mpc/Compiler/types.py\", line 5242, in get_address\n    (str(index), str(self.length)))\nIndexError: index 0, length 0\n"}