{"code": 0, "msg": "FAIL", "task_id": "2022101205115911866121", "task_name": "whole process", "create_time": "20221012051159118761", "error": "Traceback (most recent call last):\n  File \"/home/jit/service/mpc/driver/task.py\", line 60, in persist\n    r = self.__future.result()\n  File \"/usr/lib/python3.6/concurrent/futures/_base.py\", line 425, in result\n    return self.__get_result()\n  File \"/usr/lib/python3.6/concurrent/futures/_base.py\", line 384, in __get_result\n    raise self._exception\n  File \"/usr/lib/python3.6/concurrent/futures/thread.py\", line 56, in run\n    result = self.fn(*self.args, **self.kwargs)\n  File \"/home/jit/service/mpc/SrcCode/main_dynamic_function.py\", line 29, in start_mpc\n    dv = DynamicVariables(config_cpt)\n  File \"/home/jit/service/mpc/SrcCode/Source/dynamic_function.py\", line 73, in __init__\n    self.input_analysis()\n  File \"/home/jit/service/mpc/SrcCode/Source/dynamic_function.py\", line 207, in input_analysis\n    raise ValueError('THE AMOUNT OF \"data_len\" MUST BE ALIGNED WITH THE TOTAL AMOUNT OF \"input\"')\nValueError: THE AMOUNT OF \"data_len\" MUST BE ALIGNED WITH THE TOTAL AMOUNT OF \"input\"\n"}