{"code": 0, "msg": "FAIL", "task_id": "20230130090411955620162", "task_name": "whole process", "create_time": "20230130090411955689", "error": "Traceback (most recent call last):\n  File \"/home/jit/service/mpc/driver/task.py\", line 60, in persist\n    r = self.__future.result()\n  File \"/usr/lib/python3.6/concurrent/futures/_base.py\", line 425, in result\n    return self.__get_result()\n  File \"/usr/lib/python3.6/concurrent/futures/_base.py\", line 384, in __get_result\n    raise self._exception\n  File \"/usr/lib/python3.6/concurrent/futures/thread.py\", line 56, in run\n    result = self.fn(*self.args, **self.kwargs)\n  File \"/home/jit/service/mpc/SrcCode/main_dynamic_function.py\", line 21, in start_mpc\n    config_mpc = meta_js[\"MpcConfig\"]\nKeyError: 'MpcConfig'\n"}