{"code": 0, "msg": "FAIL", "task_id": "202209011016044584551", "task_name": "whole process", "create_time": "20220901101604458561", "error": "Traceback (most recent call last):\n  File \"/home/jit/service/mpc/driver/task.py\", line 60, in persist\n    r = self.__future.result()\n  File \"/usr/lib/python3.6/concurrent/futures/_base.py\", line 425, in result\n    return self.__get_result()\n  File \"/usr/lib/python3.6/concurrent/futures/_base.py\", line 384, in __get_result\n    raise self._exception\n  File \"/usr/lib/python3.6/concurrent/futures/thread.py\", line 56, in run\n    result = self.fn(*self.args, **self.kwargs)\n  File \"/home/jit/service/mpc/SrcCode/main_dynamic_function.py\", line 30, in start_mpc\n    res = dv.eval_formula()\n  File \"/home/jit/service/mpc/SrcCode/Source/dynamic_function.py\", line 394, in eval_formula\n    result = self.ai_function_map[sfunc[\"function\"]](vars, meta_para)\n  File \"/home/jit/service/mpc/SrcCode/Source/dynamic_function.py\", line 670, in calc_svc\n    res = svc(var, meta)\n  File \"/home/jit/service/mpc/SrcCode/Source/_func/svm.py\", line 91, in svc\n    Xtrt = sfix.Tensor([n_input, d_input])\nNameError: name 'd_input' is not defined\n"}