{"code": 0, "msg": "FAIL", "task_id": "202209050617101780381", "task_name": "whole process", "create_time": "20220905061710178126", "error": "Traceback (most recent call last):\n  File \"/home/jit/service/mpc/driver/task.py\", line 60, in persist\n    r = self.__future.result()\n  File \"/usr/lib/python3.6/concurrent/futures/_base.py\", line 425, in result\n    return self.__get_result()\n  File \"/usr/lib/python3.6/concurrent/futures/_base.py\", line 384, in __get_result\n    raise self._exception\n  File \"/usr/lib/python3.6/concurrent/futures/thread.py\", line 56, in run\n    result = self.fn(*self.args, **self.kwargs)\n  File \"/home/jit/service/mpc/SrcCode/main_dynamic_function.py\", line 30, in start_mpc\n    res = dv.eval_formula()\n  File \"/home/jit/service/mpc/SrcCode/Source/dynamic_function.py\", line 395, in eval_formula\n    step_results_ai[self.ai_module_dict[module]] = result\n  File \"/home/jit/service/mpc/Compiler/types.py\", line 5721, in __setitem__\n    self[index].assign(other)\n  File \"/home/jit/service/mpc/Compiler/types.py\", line 5380, in assign\n    assert len(self) >= other.size + base\nAssertionError\n"}