{"code": 0, "msg": "FAIL", "task_id": "202302271557563961852", "task_name": "whole process", "create_time": "20230227155756402667", "error": "Traceback (most recent call last):\n  File \"/home/xiumaker/Documents/service/mpc2/driver/task.py\", line 60, in persist\n    r = self.__future.result()\n  File \"/usr/lib/python3.10/concurrent/futures/_base.py\", line 451, in result\n    return self.__get_result()\n  File \"/usr/lib/python3.10/concurrent/futures/_base.py\", line 403, in __get_result\n    raise self._exception\n  File \"/usr/lib/python3.10/concurrent/futures/thread.py\", line 58, in run\n    result = self.fn(*self.args, **self.kwargs)\n  File \"/home/xiumaker/Documents/service/mpc2/SrcCode/main_dynamic_function.py\", line 41, in start_mpc\n    subprocess.run(command.split(' '))\n  File \"/usr/lib/python3.10/subprocess.py\", line 501, in run\n    with Popen(*popenargs, **kwargs) as process:\n  File \"/usr/lib/python3.10/subprocess.py\", line 969, in __init__\n    self._execute_child(args, executable, preexec_fn, close_fds,\n  File \"/usr/lib/python3.10/subprocess.py\", line 1845, in _execute_child\n    raise child_exception_type(errno_num, err_msg, err_filename)\nFileNotFoundError: [Errno 2] No such file or directory: './semi2k-party.x'\n"}