{"code": 0, "msg": "FAIL", "task_id": "202302141802535389491", "task_name": "whole process", "create_time": "20230214180253538984", "error": "Traceback (most recent call last):\n  File \"/home/xiumaker/Documents/service/mpc2/driver/task.py\", line 60, in persist\n    r = self.__future.result()\n  File \"/usr/lib/python3.10/concurrent/futures/_base.py\", line 451, in result\n    return self.__get_result()\n  File \"/usr/lib/python3.10/concurrent/futures/_base.py\", line 403, in __get_result\n    raise self._exception\n  File \"/usr/lib/python3.10/concurrent/futures/thread.py\", line 58, in run\n    result = self.fn(*self.args, **self.kwargs)\n  File \"/home/xiumaker/Documents/service/mpc2/SrcCode/main_dynamic_function.py\", line 29, in start_mpc\n    dv = DynamicVariables(config_cpt)\n  File \"/home/xiumaker/Documents/service/mpc2/SrcCode/Source/dynamic_function.py\", line 76, in __init__\n    self.log = server_log(logfile)\n  File \"/home/xiumaker/Documents/service/mpc2/SrcCode/Source/dynamic_function.py\", line 30, in server_log\n    os.makedirs(log_path)\n  File \"/usr/lib/python3.10/os.py\", line 215, in makedirs\n    makedirs(head, exist_ok=exist_ok)\n  File \"/usr/lib/python3.10/os.py\", line 225, in makedirs\n    mkdir(name, mode)\nPermissionError: [Errno 13] Permission denied: '/opt/data'\n"}