{"code": 0, "msg": "FAIL", "task_id": "2022110105360493036038", "task_name": "whole process", "create_time": "20221101053604930491", "error": "Traceback (most recent call last):\n  File \"/home/jit/service/mpc/driver/task.py\", line 60, in persist\n    r = self.__future.result()\n  File \"/usr/lib/python3.6/concurrent/futures/_base.py\", line 425, in result\n    return self.__get_result()\n  File \"/usr/lib/python3.6/concurrent/futures/_base.py\", line 384, in __get_result\n    raise self._exception\n  File \"/usr/lib/python3.6/concurrent/futures/thread.py\", line 56, in run\n    result = self.fn(*self.args, **self.kwargs)\n  File \"/home/jit/service/mpc/SrcCode/main_dynamic_function.py\", line 30, in start_mpc\n    res = dv.eval_formula()\n  File \"/home/jit/service/mpc/SrcCode/Source/dynamic_function.py\", line 258, in eval_formula\n    raise ValueError(err_msg)\nValueError: THE LENGTH: \"2\" OF DATA: \"data0-0\" DOES NOT ALIGN WITH n_length_basic: \"50\"\n"}